Workbook

Sheet Guía y Metodología
A1: Motor de Scoring de Seguros — Colsubsidio
A2: Segmentación e hiperpersonalización para autogestión de cotización — línea Familia y línea Patrimonio
B4: 1. Qué es este archivo
B5: Este workbook es el corazón analítico (motor de reglas) para la automatización del flujo de cotización de seguros de Colsubsidio: contenido → cotización → hiperpersonalización → conversación con un asesor.
B6: Se construyó con datos públicos del mercado asegurador colombiano (Fasecolda, DANE, Instituto Nacional de Cancerología, Superintendencia Financiera, entre otros — ver hoja 'Fuentes y Supuestos') porque actualmente no existe acceso a las variables ni a los datos reales de afiliados de Colsubsidio. Es un punto de partida defendible y transparente para validar con el equipo técnico de la caja de compensación una vez haya acceso a sus datos sociodemográficos, laborales y familiares reales.
B8: 2. Cómo está organizado
B9: • Guía y Metodología (esta hoja): contexto y forma de uso.
B10: • Fuentes y Supuestos: cada dato usado para calibrar los pesos, con fuente y fecha.
B11: • Variables y Categorías: las 11 variables de segmentación y sus posibles valores.
B12: • Matriz de Pesos: el motor de reglas — cada combinación variable-valor tiene un peso (0 a 5) por cada uno de los 11 seguros. Esta es la hoja que se traduce directamente a una tabla de reglas en n8n / Supabase.
B13: • Motor de Scoring (simulador): selecciona un perfil con listas desplegables y obtén el ranking de los seguros sugeridos, replicando lo que haría el asistente Hola Seggu con un usuario real.
B14: • Datos de Mercado CO: la ficha de estadísticas por cada uno de los 11 seguros, usada para justificar los pesos asignados.
B16: 3. Cómo se calcula el score (lógica del motor de reglas)
B17: Cada usuario se describe con 11 variables (edad, género, situación laboral, nivel de ingreso, composición familiar, tipo de vivienda, si es arrendador, si tiene vehículo, si tiene mascota, si usa bicicleta y si es jefatura de hogar femenina sin pareja).
... B32: 4. Para el 10% de usuarios externos (no afiliados) sin historial, ¿qué datos se les puede pedir en el formulario de autogestión sin fricción (máximo 5-6 preguntas) para alimentar este motor?

Sheet Fuentes y Supuestos
A1: # | B1: Tema | C1: Dato / estadística | D1: Fuente | E1: Fecha / corte | F1: Aplicación en el modelo
A2: 1 | B2: Penetración del seguro | C2: La penetración del seguro en Colombia (primas/PIB) cerró 2024 en 3,29%, vs. 6,2% promedio OCDE. El consumo per cápita es de ~$1.065.250 anuales. | D2: Fasecolda / La República, feb-2025 | E2: 2024 | F2: Contexto de mercado; confirma la baja cultura de aseguramiento voluntario que justifica la hiperpersonalización.
A3: 2 | B3: Informalidad laboral | C3: La informalidad laboral nacional se mantiene en 55,4% de la población ocupada (57,8% hombres, 51,9% mujeres); en 13 ciudades principales baja a ~42%. | D3: DANE, GEIH, trim. sep-nov 2025 | E3: 2025 | F3: Peso alto de V3 'Situación laboral = Informal' en accidentes personales y exequial, que son la protección más accesible sin ARL/pensión.
A4: 3 | B4: Composición de hogares | C4: Hogar promedio: 2,86 personas. 51,6% hogares biparentales, 24,3% monoparentales, 19,8% unipersonales. 46,5% de los hogares tiene jefatura femenina, de los cuales 68,8% no tiene pareja. | D4: DANE, Encuesta Nacional de Calidad de Vida (ECV) 2024 | E4: 2024 | F4: Base de V5 'Composición familiar' y V11 'Jefatura femenina sin pareja' (peso alto en Vida y Exequial).
A5: 4 | B5: Vivienda: propiedad vs. arriendo | C5: 40,4% de los hogares vive en arriendo/subarriendo; 36% posee vivienda propia pagada; 3,5% la está pagando. | D5: DANE, ECV 2024 | E5: 2024 | F5: Base de V6 'Tipo de vivienda' y V7 'Es arrendador' (relevante para Hogar y Arrendamiento).
A6: 5 | B6: Seguro de vida individual | C6: Solo ~16% de la población económicamente activa tiene seguro de vida individual. El consumo per cápita en vida es de ~$370.000/año, penetración 1,14% del PIB. | D6: Fasecolda, dic-2024 / Coriesgos | E6: 2024 | F6: Confirma bajo aseguramiento voluntario en Vida; refuerza peso alto para perfiles formales independientes y con hijos.
A7: 6 | B7: Vida — recomendación de cobertura | C7: La recomendación estándar de la industria es asegurar entre 5 y 24 veces el ingreso mensual/anual según compromisos financieros; independientes/freelancers requieren coberturas de $100-200M. | D7: HDI Seguros / Coriesgos, 2025-2026 | E7: 2025 | F7: Justifica el peso alto de Vida para 'Formal independiente/profesional' (V3) y 'Con hijos menores' (V5).
A8: 7 | B8: Salud complementaria / medicina prepagada | C8: ~4,7-4,25 millones de colombianos tienen algún esquema de salud voluntario adicional (prepagada 57%, pólizas de salud 27%, planes complementarios 16%). El régimen contributivo agrupa ~23,2 millones de afiliados. | D8: Fasecolda, Acemi, Proesa, 2024 | E8: 2024 | F8: Base para V4 'Nivel de ingreso alto' con peso alto en Salud (mayor capacidad de pago de complementarios).
A9: 8 | B9: Cáncer — incidencia por edad | C9: 53,2% de los casos de cáncer en hombres y 38,3% en mujeres ocurren en el grupo de 65+ años; 21,7% adicional está entre 55-64 años. ~81.596 casos nuevos y ~40.300 muertes anuales. | D9: Instituto Nacional de Cancerología (INC), 2022-2024 | E9: 2022-2024 | F9: Base cuantitativa directa de los pesos crecientes de 'Diagnóstico de cáncer' en V1 (edad) desde 46 años en adelante.
A10: 9 | B10: Cáncer — diferencia por sexo | C10: Los cánceres más frecuentes: próstata y estómago en hombres; mama y cuello uterino en mujeres. Incidencia similar entre sexos (151-175/100.000). | D10: INC / SciELO, estudios de incidencia 2017-2021 | E10: 2017-2021 | F10: Ajuste de peso por género (V2) en Diagnóstico de cáncer.
A11: 10 | B11: Exequial | C11: 47,5% de los hogares colombianos cuenta con alguna póliza exequial (dato agregado, incluye planes funerarios amplios); un estudio específico de seguros fúnebres reporta que solo 2,7% de los hogares (385.000 familias) tiene un seguro fúnebre formal. | D11: Superintendencia Financiera / Fasecolda / Banca de las Oportunidades, 2018; La República, 2021 | E11: 2018-2021 | F11: Estas dos cifras conviven porque miden universos distintos (planes funerarios amplios vs. pólizas fúnebres); ambas sugieren brecha de protección y oportunidad, especialmente en estratos bajos y adultos mayores.
A12: 11 | B12: Autos y motos — penetración todo riesgo | C12: Solo 12,2% del parque automotor colombiano tiene seguro voluntario todo riesgo (27% en carros, apenas 2,8-3% en motos, pese a que las motos son 61-63% del parque). | D12: Fasecolda, 2024-2025 | E12: 2024-2025 | F12: Justifica peso alto en Autos (carro) y peso medio/bajo pero con oportunidad en Moto (V8); motos con mayor accidentalidad también elevan peso en Accidentes personales.
A13: 12 | B13: Hogar — penetración | C13: Solo 9,3% de los hogares colombianos tiene seguro de vivienda voluntario (1,67 millones de hogares asegurados sobre 17,9 millones de viviendas). Más del 70% de las pólizas de hogar están atadas a créditos hipotecarios. | D13: Fasecolda / Semana, mar-2026 | E13: 2026 | F13: Justifica el peso máximo de Hogar para 'vivienda propia financiada' (V6) por la práctica casi obligatoria de asegurar la garantía hipotecaria.
... A20: 19 | B20: Nota metodológica sobre representatividad de la caja de compensación | C20: Colsubsidio afilia principalmente a trabajadores dependientes formales (cotizantes de caja de compensación) y sus familias, un segmento con mayor formalidad relativa que el promedio nacional (55,4% de informalidad). | D20: Supuesto de trabajo — Colsubsidio no publica esta segmentación específica públicamente | E20: N/A | F20: Advertencia: el peso relativo de 'Formal dependiente' probablemente deba subir una vez se valide con datos reales de la base de afiliados de Colsubsidio (ver pregunta 3 de la Guía).

Sheet Variables y Categorías
A1: Variables de segmentación del motor de scoring (11 variables)
A3: Código | B3: Variable | C3: Categorías posibles | D3: Fuente / racional resumido | F3: V1 - Rango de edad | G3: V2 - Género | H3: V3 - Situación laboral | I3: V4 - Nivel de ingreso mensual | J3: V5 - Composición familiar | K3: V6 - Tipo de vivienda | L3: V7 - ¿Es propietario que arrienda un inmueble a terceros? | M3: V8 - Tenencia de vehículo | N3: V9 - ¿Tiene mascota (perro o gato)? | O3: V10 - ¿Usa bicicleta como transporte o deporte habitual? | P3: V11 - ¿Es jefatura de hogar femenina sin pareja?
A4: V1 | B4: Rango de edad | C4: 18-25 años | 26-35 años | 36-45 años | 46-55 años | 56-65 años | 66+ años | D4: DANE (composición etaria), INC (incidencia de cáncer por edad), Fasecolda (perfil comprador vida y autos). | F4: 18-25 años | G4: Masculino | H4: Formal dependiente | I4: Bajo (< $1.3M) | J4: Soltero(a) sin hijos | K4: Propia pagada | L4: Sí | M4: Carro | N4: Sí | O4: Sí | P4: Sí
A5: V2 | B5: Género | C5: Masculino | Femenino | D5: DANE (jefatura femenina de hogar), INC (cáncer por sexo), SURA (76% clientes de seguros de mascotas son mujeres). | F5: 26-35 años | G5: Femenino | H5: Formal independiente / profesional | I5: Medio ($1.3M - $4.6M) | J5: Pareja sin hijos | K5: Propia financiada (hipoteca) | L5: No | M5: Moto | N5: No | O5: No | P5: No
A6: V3 | B6: Situación laboral | C6: Formal dependiente | Formal independiente / profesional | Informal / cuenta propia sin cotización | D6: DANE (informalidad 55,4%), Fasecolda (vida individual en independientes/freelancers). | F6: 36-45 años | H6: Informal / cuenta propia sin cotización | I6: Alto (> $4.6M) | J6: Con hijos menores de edad | K6: Arrendada | M6: No tiene
A7: V4 | B7: Nivel de ingreso mensual | C7: Bajo (< $1.3M) | Medio ($1.3M - $4.6M) | Alto (> $4.6M) | D7: DANE (umbrales de clase social 2024), Fasecolda (consumo per cápita en seguros). | F7: 46-55 años | J7: Monoparental con hijos
A8: V5 | B8: Composición familiar | C8: Soltero(a) sin hijos | Pareja sin hijos | Con hijos menores de edad | Monoparental con hijos | Multigeneracional / adulto mayor a cargo | D8: DANE ECV 2024 (51,6% biparental, 24,3% monoparental, 19,8% unipersonal). | F8: 56-65 años | J8: Multigeneracional / adulto mayor a cargo
A9: V6 | B9: Tipo de vivienda | C9: Propia pagada | Propia financiada (hipoteca) | Arrendada | D9: DANE ECV 2024 (40,4% en arriendo, 36% propia pagada); Fasecolda (70%+ pólizas de hogar atadas a hipoteca). | F9: 66+ años
A10: V7 | B10: ¿Es propietario que arrienda un inmueble a terceros? | C10: Sí | No | D10: Mercado de seguros de arrendamiento (Coriesgos, Fasecolda) — variable binaria de oportunidad de venta cruzada.
A11: V8 | B11: Tenencia de vehículo | C11: Carro | Moto | No tiene | D11: Fasecolda (12,2% parque automotor con todo riesgo; motos solo 2,8-3% pese a ser 61-63% del parque).
A12: V9 | B12: ¿Tiene mascota (perro o gato)? | C12: Sí | No | D12: DANE / Kantar (60-70% de hogares colombianos tiene mascota).
A13: V10 | B13: ¿Usa bicicleta como transporte o deporte habitual? | C13: Sí | No | D13: Secretaría de Seguridad de Bogotá (hurto de bicicletas cada 2,5 horas en 2025).
A14: V11 | B14: ¿Es jefatura de hogar femenina sin pareja? | C14: Sí | No | D14: DANE ECV 2024 (46,5% jefatura femenina, 68,8% de ellas sin pareja) — foco especial del ICP de soycaropinzón.

Sheet Matriz de Pesos
A1: Matriz de Pesos — Motor de reglas (0 = sin relevancia, 5 = máxima prioridad)
D2: Familia | E2: Familia | F2: Familia | G2: Familia | H2: Familia | I2: Familia | J2: Familia | K2: Patrimonio | L2: Patrimonio | M2: Patrimonio | N2: Patrimonio
A3: Clave (uso interno) | B3: Variable | C3: Categoría | D3: Vida | E3: Accidentes personales | F3: Renta por hospitalización | G3: Diagnóstico positivo de cáncer | H3: Póliza de salud | I3: Exequial familiar | J3: Seguro de mascotas | K3: Todo riesgo autos y motos | L3: Todo riesgo hogar | M3: Bicicletas | N3: Arrendamiento | O3: Racional / fuente resumida
A4: V1|18-25 años | B4: V1 - Rango de edad | C4: 18-25 años | D4: 1 | E4: 3 | F4: 1 | G4: 0 | H4: 2 | I4: 1 | J4: 3 | K4: 1 | L4: 1 | M4: 4 | N4: 1 | O4: Prioridad en bicicleta y mascota (perfil joven urbano); vida y cáncer casi irrelevantes a esta edad.
A5: V1|26-35 años | C5: 26-35 años | D5: 3 | E5: 3 | F5: 2 | G5: 1 | H5: 3 | I5: 1 | J5: 4 | K5: 3 | L5: 2 | M5: 3 | N5: 3 | O5: Edad pico de tenencia de mascota (30-50 años, SURA) y de arriendo (DANE); comienza a evaluar vida y autos.
A6: V1|36-45 años | C6: 36-45 años | D6: 5 | E6: 2 | F6: 3 | G6: 2 | H6: 3 | I6: 2 | J6: 3 | K6: 4 | L6: 4 | M6: 2 | N6: 3 | O6: Pico de compra de vivienda y auto propio; arranca la lógica HLV/DIME de vida por responsabilidades familiares.
A7: V1|46-55 años | C7: 46-55 años | D7: 4 | E7: 2 | F7: 4 | G7: 4 | H7: 4 | I7: 3 | J7: 2 | K7: 4 | L7: 4 | M7: 1 | N7: 2 | O7: El 21,7% de casos de cáncer ocurre en 55-64 años, por lo que el riesgo ya es relevante desde los 46; renta por hospitalización sube.
A8: V1|56-65 años | C8: 56-65 años | D8: 2 | E8: 2 | F8: 5 | G8: 5 | H8: 4 | I8: 4 | J8: 1 | K8: 3 | L8: 3 | M8: 1 | N8: 1 | O8: Cáncer e renta hospitalización en niveles altos; exequial empieza a ganar peso.
A9: V1|66+ años | C9: 66+ años | D9: 1 | E9: 2 | F9: 5 | G9: 5 | H9: 3 | I9: 5 | J9: 1 | K9: 1 | L9: 2 | M9: 0 | N9: 0 | O9: 53,2% de los casos de cáncer en hombres ocurre en 65+ años (INC); exequial es prioridad máxima; vida ya no es asegurable/rentable a esta edad.
A10: V2|Masculino | B10: V2 - Género | C10: Masculino | D10: 3 | E10: 3 | F10: 2 | G10: 3 | H10: 2 | I10: 2 | J10: 2 | K10: 3 | L10: 2 | M10: 3 | N10: 2 | O10: Mayor peso relativo en autos/motos y cáncer de próstata/estómago.
A11: V2|Femenino | C11: Femenino | D11: 4 | E11: 2 | F11: 3 | G11: 4 | H11: 3 | I11: 3 | J11: 4 | K11: 2 | L11: 2 | M11: 2 | N11: 2 | O11: 76% de clientes de seguros de mascotas son mujeres (SURA); mayor probabilidad de jefatura de hogar; cáncer de mama/cuello uterino.
A12: V3|Formal dependiente | B12: V3 - Situación laboral | C12: Formal dependiente | D12: 2 | E12: 1 | F12: 1 | G12: 2 | H12: 3 | I12: 2 | J12: 2 | K12: 3 | L12: 3 | M12: 2 | N12: 2 | O12: Ya cuenta con EPS, ARL y pensión vía empleador; prioridad en complementarios (salud, autos, hogar) por mayor estabilidad de ingreso.
A13: V3|Formal independiente / profesional | C13: Formal independiente / profesional | D13: 5 | E13: 4 | F13: 4 | G13: 3 | H13: 4 | I13: 2 | J13: 2 | K13: 3 | L13: 3 | M13: 2 | N13: 3 | O13: Sin seguro de vida grupal empresarial ni ARL automática; el 84% de la PEA no tiene vida individual (Fasecolda).
A14: V3|Informal / cuenta propia sin cotización | C14: Informal / cuenta propia sin cotización | D14: 3 | E14: 5 | F14: 3 | G14: 1 | H14: 1 | I14: 4 | J14: 1 | K14: 1 | L14: 1 | M14: 1 | N14: 1 | O14: 55,4% de la población ocupada (DANE); sin ARL ni pensión, accidentes personales y exequial son la protección más urgente y accesible.
A15: V4|Bajo (< $1.3M) | B15: V4 - Nivel de ingreso mensual | C15: Bajo (< $1.3M) | D15: 1 | E15: 3 | F15: 1 | G15: 1 | H15: 0 | I15: 4 | J15: 1 | K15: 0 | L15: 0 | M15: 2 | N15: 0 | O15: Capacidad de pago limitada a productos de prima baja; exequial tiene fuerte arraigo cultural en estratos bajos (47,5% de hogares con algún esquema).
A16: V4|Medio ($1.3M - $4.6M) | C16: Medio ($1.3M - $4.6M) | D16: 3 | E16: 3 | F16: 3 | G16: 3 | H16: 3 | I16: 2 | J16: 3 | K16: 3 | L16: 3 | M16: 2 | N16: 2 | O16: Segmento de clase media (32-34% de la población, DANE); es el ICP principal de Seggu (familias con carro).
A17: V4|Alto (> $4.6M) | C17: Alto (> $4.6M) | D17: 4 | E17: 2 | F17: 3 | G17: 3 | H17: 5 | I17: 1 | J17: 4 | K17: 5 | L17: 5 | M17: 1 | N17: 4 | O17: Mayor probabilidad de vivienda y vehículo propios; foco en salud complementaria/prepagada y patrimonio.
A18: V5|Soltero(a) sin hijos | B18: V5 - Composición familiar | C18: Soltero(a) sin hijos | D18: 1 | E18: 3 | F18: 1 | G18: 1 | H18: 2 | I18: 1 | J18: 4 | K18: 2 | L18: 1 | M18: 4 | N18: 1 | O18: Sin dependientes económicos; prioridad en mascota, bicicleta y accidentes personales sobre vida.
A19: V5|Pareja sin hijos | C19: Pareja sin hijos | D19: 2 | E19: 2 | F19: 2 | G19: 2 | H19: 3 | I19: 2 | J19: 4 | K19: 3 | L19: 4 | M19: 2 | N19: 2 | O19: Enfoque en patrimonio compartido (hogar, auto) y mascota.
A20: V5|Con hijos menores de edad | C20: Con hijos menores de edad | D20: 5 | E20: 3 | F20: 4 | G20: 3 | H20: 5 | I20: 3 | J20: 2 | K20: 3 | L20: 4 | M20: 1 | N20: 1 | O20: Máxima prioridad en vida y salud familiar (lógica HLV/DIME); también sube renta por hospitalización.
A21: V5|Monoparental con hijos | C21: Monoparental con hijos | D21: 5 | E21: 3 | F21: 3 | G21: 2 | H21: 3 | I21: 4 | J21: 1 | K21: 1 | L21: 2 | M21: 1 | N21: 1 | O21: 24,3% de los hogares (DANE); jefe de hogar es el único proveedor, por lo que vida y exequial son críticos.
A22: V5|Multigeneracional / adulto mayor a cargo | C22: Multigeneracional / adulto mayor a cargo | D22: 3 | E22: 2 | F22: 5 | G22: 4 | H22: 3 | I22: 5 | J22: 1 | K22: 1 | L22: 2 | M22: 0 | N22: 0 | O22: Mayor probabilidad de necesitar renta por hospitalización, diagnóstico de cáncer y exequial para el adulto mayor.
A23: V6|Propia pagada | B23: V6 - Tipo de vivienda | C23: Propia pagada | D23: 2 | E23: 1 | F23: 1 | G23: 1 | H23: 2 | I23: 1 | J23: 2 | K23: 2 | L23: 5 | M23: 1 | N23: 1 | O23: Activo ya consolidado sin deuda; el seguro de hogar es 100% decisión voluntaria de protección patrimonial.
A24: V6|Propia financiada (hipoteca) | C24: Propia financiada (hipoteca) | D24: 3 | E24: 1 | F24: 1 | G24: 1 | H24: 2 | I24: 1 | J24: 1 | K24: 2 | L24: 5 | M24: 1 | N24: 1 | O24: Más del 70% de las pólizas de hogar están atadas a créditos hipotecarios (Fasecolda) — casi obligatorio en la práctica.
A25: V6|Arrendada | C25: Arrendada | D25: 1 | E25: 1 | F25: 1 | G25: 1 | H25: 1 | I25: 1 | J25: 2 | K25: 1 | L25: 1 | M25: 1 | N25: 0 | O25: Menor necesidad de seguro de hogar (activo no propio); puede necesitar seguro de contenidos básico.
A26: V7|Sí | B26: V7 - ¿Es propietario que arrienda un inmueble a terceros? | C26: Sí | D26: 0 | E26: 0 | F26: 0 | G26: 0 | H26: 0 | I26: 0 | J26: 0 | K26: 0 | L26: 1 | M26: 0 | N26: 5 | O26: Variable binaria de oportunidad de venta cruzada específica (arrendamiento a terceros).
A27: V7|No | C27: No | D27: 0 | E27: 0 | F27: 0 | G27: 0 | H27: 0 | I27: 0 | J27: 0 | K27: 0 | L27: 0 | M27: 0 | N27: 0 | O27: Sin relevancia en esta variable.
A28: V8|Carro | B28: V8 - Tenencia de vehículo | C28: Carro | D28: 1 | E28: 1 | F28: 0 | G28: 0 | H28: 0 | I28: 0 | J28: 0 | K28: 5 | L28: 0 | M28: 0 | N28: 0 | O28: Solo 12,2% del parque automotor tiene todo riesgo voluntario (Fasecolda) — alta oportunidad para el segmento con carro.
A29: V8|Moto | C29: Moto | D29: 2 | E29: 3 | F29: 1 | G29: 0 | H29: 0 | I29: 0 | J29: 0 | K29: 3 | L29: 0 | M29: 0 | N29: 0 | O29: Las motos son 61-63% del parque automotor pero solo 2,8-3% tiene todo riesgo — gran brecha; mayor accidentalidad también sube accidentes personales.
A30: V8|No tiene | C30: No tiene | D30: 0 | E30: 0 | F30: 0 | G30: 0 | H30: 0 | I30: 0 | J30: 0 | K30: 0 | L30: 0 | M30: 0 | N30: 0 | O30: Sin relevancia para productos de vehículo.
A31: V9|Sí | B31: V9 - ¿Tiene mascota (perro o gato)? | C31: Sí | D31: 0 | E31: 0 | F31: 0 | G31: 0 | H31: 0 | I31: 0 | J31: 5 | K31: 0 | L31: 0 | M31: 0 | N31: 0 | O31: Variable binaria de oportunidad de venta cruzada específica (arrendamiento a terceros).
A32: V9|No | C32: No | D32: 0 | E32: 0 | F32: 0 | G32: 0 | H32: 0 | I32: 0 | J32: 0 | K32: 0 | L32: 0 | M32: 0 | N32: 0 | O32: Sin relevancia en esta variable.
A33: V10|Sí | B33: V10 - ¿Usa bicicleta como transporte o deporte habitual? | C33: Sí | D33: 0 | E33: 2 | F33: 0 | G33: 0 | H33: 0 | I33: 0 | J33: 0 | K33: 0 | L33: 0 | M33: 5 | N33: 0 | O33: Variable binaria de oportunidad de venta cruzada específica (arrendamiento a terceros).
A34: V10|No | C34: No | D34: 0 | E34: 0 | F34: 0 | G34: 0 | H34: 0 | I34: 0 | J34: 0 | K34: 0 | L34: 0 | M34: 0 | N34: 0 | O34: Sin relevancia en esta variable.
A35: V11|Sí | B35: V11 - ¿Es jefatura de hogar femenina sin pareja? | C35: Sí | D35: 3 | E35: 1 | F35: 1 | G35: 1 | H35: 1 | I35: 2 | J35: 0 | K35: 0 | L35: 0 | M35: 0 | N35: 0 | O35: Variable binaria de oportunidad de venta cruzada específica (arrendamiento a terceros).
A36: V11|No | C36: No | D36: 0 | E36: 0 | F36: 0 | G36: 0 | H36: 0 | I36: 0 | J36: 0 | K36: 0 | L36: 0 | M36: 0 | N36: 0 | O36: Sin relevancia en esta variable.
B38: PUNTAJE MÁXIMO TEÓRICO | D38: =MAX(D4:D9)+MAX(D10:D11)+MAX(D12:D14)+MAX(D15:D17)+MAX(D18:D22)+MAX(D23:D25)+MAX(D26:D27)+MAX(D28:D30)+MAX(D31:D32)+MAX(D33:D34)+MAX(D35:D36) -> 31 | E38: =MAX(E4:E9)+MAX(E10:E11)+MAX(E12:E14)+MAX(E15:E17)+MAX(E18:E22)+MAX(E23:E25)+MAX(E26:E27)+MAX(E28:E30)+MAX(E31:E32)+MAX(E33:E34)+MAX(E35:E36) -> 24 | F38: =MAX(F4:F9)+MAX(F10:F11)+MAX(F12:F14)+MAX(F15:F17)+MAX(F18:F22)+MAX(F23:F25)+MAX(F26:F27)+MAX(F28:F30)+MAX(F31:F32)+MAX(F33:F34)+MAX(F35:F36) -> 23 | G38: =MAX(G4:G9)+MAX(G10:G11)+MAX(G12:G14)+MAX(G15:G17)+MAX(G18:G22)+MAX(G23:G25)+MAX(G26:G27)+MAX(G28:G30)+MAX(G31:G32)+MAX(G33:G34)+MAX(G35:G36) -> 21 | H38: =MAX(H4:H9)+MAX(H10:H11)+MAX(H12:H14)+MAX(H15:H17)+MAX(H18:H22)+MAX(H23:H25)+MAX(H26:H27)+MAX(H28:H30)+MAX(H31:H32)+MAX(H33:H34)+MAX(H35:H36) -> 24 | I38: =MAX(I4:I9)+MAX(I10:I11)+MAX(I12:I14)+MAX(I15:I17)+MAX(I18:I22)+MAX(I23:I25)+MAX(I26:I27)+MAX(I28:I30)+MAX(I31:I32)+MAX(I33:I34)+MAX(I35:I36) -> 24 | J38: =MAX(J4:J9)+MAX(J10:J11)+MAX(J12:J14)+MAX(J15:J17)+MAX(J18:J22)+MAX(J23:J25)+MAX(J26:J27)+MAX(J28:J30)+MAX(J31:J32)+MAX(J33:J34)+MAX(J35:J36) -> 25 | K38: =MAX(K4:K9)+MAX(K10:K11)+MAX(K12:K14)+MAX(K15:K17)+MAX(K18:K22)+MAX(K23:K25)+MAX(K26:K27)+MAX(K28:K30)+MAX(K31:K32)+MAX(K33:K34)+MAX(K35:K36) -> 25 | ... N38: =MAX(N4:N9)+MAX(N10:N11)+MAX(N12:N14)+MAX(N15:N17)+MAX(N18:N22)+MAX(N23:N25)+MAX(N26:N27)+MAX(N28:N30)+MAX(N31:N32)+MAX(N33:N34)+MAX(N35:N36) -> 20

Sheet Motor de Scoring
A1: Motor de Scoring — Simulador de perfil
A2: Selecciona un perfil en la columna amarilla y el ranking de seguros sugeridos se calcula automáticamente.
A4: Código | B4: Variable | C4: Tu selección | D4: Clave (uso interno)
A5: V1 | B5: Rango de edad | C5: 36-45 años | D5: =$A5&"|"&$C5 -> V1|36-45 años
A6: V2 | B6: Género | C6: Femenino | D6: =$A6&"|"&$C6 -> V2|Femenino
A7: V3 | B7: Situación laboral | C7: Formal independiente / profesional | D7: =$A7&"|"&$C7 -> V3|Formal independiente / profesional
A8: V4 | B8: Nivel de ingreso mensual | C8: Medio ($1.3M - $4.6M) | D8: =$A8&"|"&$C8 -> V4|Medio ($1.3M - $4.6M)
A9: V5 | B9: Composición familiar | C9: Con hijos menores de edad | D9: =$A9&"|"&$C9 -> V5|Con hijos menores de edad
A10: V6 | B10: Tipo de vivienda | C10: Arrendada | D10: =$A10&"|"&$C10 -> V6|Arrendada
A11: V7 | B11: ¿Es propietario que arrienda un inmueble a terceros? | C11: No | D11: =$A11&"|"&$C11 -> V7|No
A12: V8 | B12: Tenencia de vehículo | C12: Carro | D12: =$A12&"|"&$C12 -> V8|Carro
A13: V9 | B13: ¿Tiene mascota (perro o gato)? | C13: Sí | D13: =$A13&"|"&$C13 -> V9|Sí
A14: V10 | B14: ¿Usa bicicleta como transporte o deporte habitual? | C14: No | D14: =$A14&"|"&$C14 -> V10|No
A15: V11 | B15: ¿Es jefatura de hogar femenina sin pareja? | C15: No | D15: =$A15&"|"&$C15 -> V11|No
A18: Detalle de puntaje por variable y producto
A19: Variable | B19: Vida | C19: Accidentes personales | D19: Renta por hospitalización | E19: Diagnóstico positivo de cáncer | F19: Póliza de salud | G19: Exequial familiar | H19: Seguro de mascotas | I19: Todo riesgo autos y motos | J19: Todo riesgo hogar | K19: Bicicletas | L19: Arrendamiento
A20: Rango de edad | B20: =IFERROR(INDEX('Matriz de Pesos'!$D$4:$D$36,MATCH($D$5,'Matriz de Pesos'!$A$4:$A$36,0)),0) -> 5 | C20: =IFERROR(INDEX('Matriz de Pesos'!$E$4:$E$36,MATCH($D$5,'Matriz de Pesos'!$A$4:$A$36,0)),0) -> 2 | D20: =IFERROR(INDEX('Matriz de Pesos'!$F$4:$F$36,MATCH($D$5,'Matriz de Pesos'!$A$4:$A$36,0)),0) -> 3 | E20: =IFERROR(INDEX('Matriz de Pesos'!$G$4:$G$36,MATCH($D$5,'Matriz de Pesos'!$A$4:$A$36,0)),0) -> 2 | F20: =IFERROR(INDEX('Matriz de Pesos'!$H$4:$H$36,MATCH($D$5,'Matriz de Pesos'!$A$4:$A$36,0)),0) -> 3 | G20: =IFERROR(INDEX('Matriz de Pesos'!$I$4:$I$36,MATCH($D$5,'Matriz de Pesos'!$A$4:$A$36,0)),0) -> 2 | H20: =IFERROR(INDEX('Matriz de Pesos'!$J$4:$J$36,MATCH($D$5,'Matriz de Pesos'!$A$4:$A$36,0)),0) -> 3 | I20: =IFERROR(INDEX('Matriz de Pesos'!$K$4:$K$36,MATCH($D$5,'Matriz de Pesos'!$A$4:$A$36,0)),0) -> 4 | J20: =IFERROR(INDEX('Matriz de Pesos'!$L$4:$L$36,MATCH($D$5,'Matriz de Pesos'!$A$4:$A$36,0)),0) -> 4 | K20: =IFERROR(INDEX('Matriz de Pesos'!$M$4:$M$36,MATCH($D$5,'Matriz de Pesos'!$A$4:$A$36,0)),0) -> 2 | L20: =IFERROR(INDEX('Matriz de Pesos'!$N$4:$N$36,MATCH($D$5,'Matriz de Pesos'!$A$4:$A$36,0)),0) -> 3
A21: Género | B21: =IFERROR(INDEX('Matriz de Pesos'!$D$4:$D$36,MATCH($D$6,'Matriz de Pesos'!$A$4:$A$36,0)),0) -> 4 | C21: =IFERROR(INDEX('Matriz de Pesos'!$E$4:$E$36,MATCH($D$6,'Matriz de Pesos'!$A$4:$A$36,0)),0) -> 2 | D21: =IFERROR(INDEX('Matriz de Pesos'!$F$4:$F$36,MATCH($D$6,'Matriz de Pesos'!$A$4:$A$36,0)),0) -> 3 | E21: =IFERROR(INDEX('Matriz de Pesos'!$G$4:$G$36,MATCH($D$6,'Matriz de Pesos'!$A$4:$A$36,0)),0) -> 4 | F21: =IFERROR(INDEX('Matriz de Pesos'!$H$4:$H$36,MATCH($D$6,'Matriz de Pesos'!$A$4:$A$36,0)),0) -> 3 | G21: =IFERROR(INDEX('Matriz de Pesos'!$I$4:$I$36,MATCH($D$6,'Matriz de Pesos'!$A$4:$A$36,0)),0) -> 3 | H21: =IFERROR(INDEX('Matriz de Pesos'!$J$4:$J$36,MATCH($D$6,'Matriz de Pesos'!$A$4:$A$36,0)),0) -> 4 | I21: =IFERROR(INDEX('Matriz de Pesos'!$K$4:$K$36,MATCH($D$6,'Matriz de Pesos'!$A$4:$A$36,0)),0) -> 2 | J21: =IFERROR(INDEX('Matriz de Pesos'!$L$4:$L$36,MATCH($D$6,'Matriz de Pesos'!$A$4:$A$36,0)),0) -> 2 | K21: =IFERROR(INDEX('Matriz de Pesos'!$M$4:$M$36,MATCH($D$6,'Matriz de Pesos'!$A$4:$A$36,0)),0) -> 2 | L21: =IFERROR(INDEX('Matriz de Pesos'!$N$4:$N$36,MATCH($D$6,'Matriz de Pesos'!$A$4:$A$36,0)),0) -> 2
A22: Situación laboral | B22: =IFERROR(INDEX('Matriz de Pesos'!$D$4:$D$36,MATCH($D$7,'Matriz de Pesos'!$A$4:$A$36,0)),0) -> 5 | C22: =IFERROR(INDEX('Matriz de Pesos'!$E$4:$E$36,MATCH($D$7,'Matriz de Pesos'!$A$4:$A$36,0)),0) -> 4 | D22: =IFERROR(INDEX('Matriz de Pesos'!$F$4:$F$36,MATCH($D$7,'Matriz de Pesos'!$A$4:$A$36,0)),0) -> 4 | E22: =IFERROR(INDEX('Matriz de Pesos'!$G$4:$G$36,MATCH($D$7,'Matriz de Pesos'!$A$4:$A$36,0)),0) -> 3 | F22: =IFERROR(INDEX('Matriz de Pesos'!$H$4:$H$36,MATCH($D$7,'Matriz de Pesos'!$A$4:$A$36,0)),0) -> 4 | G22: =IFERROR(INDEX('Matriz de Pesos'!$I$4:$I$36,MATCH($D$7,'Matriz de Pesos'!$A$4:$A$36,0)),0) -> 2 | H22: =IFERROR(INDEX('Matriz de Pesos'!$J$4:$J$36,MATCH($D$7,'Matriz de Pesos'!$A$4:$A$36,0)),0) -> 2 | I22: =IFERROR(INDEX('Matriz de Pesos'!$K$4:$K$36,MATCH($D$7,'Matriz de Pesos'!$A$4:$A$36,0)),0) -> 3 | J22: =IFERROR(INDEX('Matriz de Pesos'!$L$4:$L$36,MATCH($D$7,'Matriz de Pesos'!$A$4:$A$36,0)),0) -> 3 | K22: =IFERROR(INDEX('Matriz de Pesos'!$M$4:$M$36,MATCH($D$7,'Matriz de Pesos'!$A$4:$A$36,0)),0) -> 2 | L22: =IFERROR(INDEX('Matriz de Pesos'!$N$4:$N$36,MATCH($D$7,'Matriz de Pesos'!$A$4:$A$36,0)),0) -> 3
A23: Nivel de ingreso mensual | B23: =IFERROR(INDEX('Matriz de Pesos'!$D$4:$D$36,MATCH($D$8,'Matriz de Pesos'!$A$4:$A$36,0)),0) -> 3 | C23: =IFERROR(INDEX('Matriz de Pesos'!$E$4:$E$36,MATCH($D$8,'Matriz de Pesos'!$A$4:$A$36,0)),0) -> 3 | D23: =IFERROR(INDEX('Matriz de Pesos'!$F$4:$F$36,MATCH($D$8,'Matriz de Pesos'!$A$4:$A$36,0)),0) -> 3 | E23: =IFERROR(INDEX('Matriz de Pesos'!$G$4:$G$36,MATCH($D$8,'Matriz de Pesos'!$A$4:$A$36,0)),0) -> 3 | F23: =IFERROR(INDEX('Matriz de Pesos'!$H$4:$H$36,MATCH($D$8,'Matriz de Pesos'!$A$4:$A$36,0)),0) -> 3 | G23: =IFERROR(INDEX('Matriz de Pesos'!$I$4:$I$36,MATCH($D$8,'Matriz de Pesos'!$A$4:$A$36,0)),0) -> 2 | H23: =IFERROR(INDEX('Matriz de Pesos'!$J$4:$J$36,MATCH($D$8,'Matriz de Pesos'!$A$4:$A$36,0)),0) -> 3 | I23: =IFERROR(INDEX('Matriz de Pesos'!$K$4:$K$36,MATCH($D$8,'Matriz de Pesos'!$A$4:$A$36,0)),0) -> 3 | J23: =IFERROR(INDEX('Matriz de Pesos'!$L$4:$L$36,MATCH($D$8,'Matriz de Pesos'!$A$4:$A$36,0)),0) -> 3 | K23: =IFERROR(INDEX('Matriz de Pesos'!$M$4:$M$36,MATCH($D$8,'Matriz de Pesos'!$A$4:$A$36,0)),0) -> 2 | L23: =IFERROR(INDEX('Matriz de Pesos'!$N$4:$N$36,MATCH($D$8,'Matriz de Pesos'!$A$4:$A$36,0)),0) -> 2
A24: Composición familiar | B24: =IFERROR(INDEX('Matriz de Pesos'!$D$4:$D$36,MATCH($D$9,'Matriz de Pesos'!$A$4:$A$36,0)),0) -> 5 | C24: =IFERROR(INDEX('Matriz de Pesos'!$E$4:$E$36,MATCH($D$9,'Matriz de Pesos'!$A$4:$A$36,0)),0) -> 3 | D24: =IFERROR(INDEX('Matriz de Pesos'!$F$4:$F$36,MATCH($D$9,'Matriz de Pesos'!$A$4:$A$36,0)),0) -> 4 | E24: =IFERROR(INDEX('Matriz de Pesos'!$G$4:$G$36,MATCH($D$9,'Matriz de Pesos'!$A$4:$A$36,0)),0) -> 3 | F24: =IFERROR(INDEX('Matriz de Pesos'!$H$4:$H$36,MATCH($D$9,'Matriz de Pesos'!$A$4:$A$36,0)),0) -> 5 | G24: =IFERROR(INDEX('Matriz de Pesos'!$I$4:$I$36,MATCH($D$9,'Matriz de Pesos'!$A$4:$A$36,0)),0) -> 3 | H24: =IFERROR(INDEX('Matriz de Pesos'!$J$4:$J$36,MATCH($D$9,'Matriz de Pesos'!$A$4:$A$36,0)),0) -> 2 | I24: =IFERROR(INDEX('Matriz de Pesos'!$K$4:$K$36,MATCH($D$9,'Matriz de Pesos'!$A$4:$A$36,0)),0) -> 3 | J24: =IFERROR(INDEX('Matriz de Pesos'!$L$4:$L$36,MATCH($D$9,'Matriz de Pesos'!$A$4:$A$36,0)),0) -> 4 | K24: =IFERROR(INDEX('Matriz de Pesos'!$M$4:$M$36,MATCH($D$9,'Matriz de Pesos'!$A$4:$A$36,0)),0) -> 1 | L24: =IFERROR(INDEX('Matriz de Pesos'!$N$4:$N$36,MATCH($D$9,'Matriz de Pesos'!$A$4:$A$36,0)),0) -> 1
A25: Tipo de vivienda | B25: =IFERROR(INDEX('Matriz de Pesos'!$D$4:$D$36,MATCH($D$10,'Matriz de Pesos'!$A$4:$A$36,0)),0) -> 1 | C25: =IFERROR(INDEX('Matriz de Pesos'!$E$4:$E$36,MATCH($D$10,'Matriz de Pesos'!$A$4:$A$36,0)),0) -> 1 | D25: =IFERROR(INDEX('Matriz de Pesos'!$F$4:$F$36,MATCH($D$10,'Matriz de Pesos'!$A$4:$A$36,0)),0) -> 1 | E25: =IFERROR(INDEX('Matriz de Pesos'!$G$4:$G$36,MATCH($D$10,'Matriz de Pesos'!$A$4:$A$36,0)),0) -> 1 | F25: =IFERROR(INDEX('Matriz de Pesos'!$H$4:$H$36,MATCH($D$10,'Matriz de Pesos'!$A$4:$A$36,0)),0) -> 1 | G25: =IFERROR(INDEX('Matriz de Pesos'!$I$4:$I$36,MATCH($D$10,'Matriz de Pesos'!$A$4:$A$36,0)),0) -> 1 | H25: =IFERROR(INDEX('Matriz de Pesos'!$J$4:$J$36,MATCH($D$10,'Matriz de Pesos'!$A$4:$A$36,0)),0) -> 2 | I25: =IFERROR(INDEX('Matriz de Pesos'!$K$4:$K$36,MATCH($D$10,'Matriz de Pesos'!$A$4:$A$36,0)),0) -> 1 | J25: =IFERROR(INDEX('Matriz de Pesos'!$L$4:$L$36,MATCH($D$10,'Matriz de Pesos'!$A$4:$A$36,0)),0) -> 1 | K25: =IFERROR(INDEX('Matriz de Pesos'!$M$4:$M$36,MATCH($D$10,'Matriz de Pesos'!$A$4:$A$36,0)),0) -> 1 | L25: =IFERROR(INDEX('Matriz de Pesos'!$N$4:$N$36,MATCH($D$10,'Matriz de Pesos'!$A$4:$A$36,0)),0) -> 0
A26: ¿Es propietario que arrienda un inmueble a terceros? | B26: =IFERROR(INDEX('Matriz de Pesos'!$D$4:$D$36,MATCH($D$11,'Matriz de Pesos'!$A$4:$A$36,0)),0) -> 0 | C26: =IFERROR(INDEX('Matriz de Pesos'!$E$4:$E$36,MATCH($D$11,'Matriz de Pesos'!$A$4:$A$36,0)),0) -> 0 | D26: =IFERROR(INDEX('Matriz de Pesos'!$F$4:$F$36,MATCH($D$11,'Matriz de Pesos'!$A$4:$A$36,0)),0) -> 0 | E26: =IFERROR(INDEX('Matriz de Pesos'!$G$4:$G$36,MATCH($D$11,'Matriz de Pesos'!$A$4:$A$36,0)),0) -> 0 | F26: =IFERROR(INDEX('Matriz de Pesos'!$H$4:$H$36,MATCH($D$11,'Matriz de Pesos'!$A$4:$A$36,0)),0) -> 0 | G26: =IFERROR(INDEX('Matriz de Pesos'!$I$4:$I$36,MATCH($D$11,'Matriz de Pesos'!$A$4:$A$36,0)),0) -> 0 | H26: =IFERROR(INDEX('Matriz de Pesos'!$J$4:$J$36,MATCH($D$11,'Matriz de Pesos'!$A$4:$A$36,0)),0) -> 0 | I26: =IFERROR(INDEX('Matriz de Pesos'!$K$4:$K$36,MATCH($D$11,'Matriz de Pesos'!$A$4:$A$36,0)),0) -> 0 | J26: =IFERROR(INDEX('Matriz de Pesos'!$L$4:$L$36,MATCH($D$11,'Matriz de Pesos'!$A$4:$A$36,0)),0) -> 0 | K26: =IFERROR(INDEX('Matriz de Pesos'!$M$4:$M$36,MATCH($D$11,'Matriz de Pesos'!$A$4:$A$36,0)),0) -> 0 | L26: =IFERROR(INDEX('Matriz de Pesos'!$N$4:$N$36,MATCH($D$11,'Matriz de Pesos'!$A$4:$A$36,0)),0) -> 0
A27: Tenencia de vehículo | B27: =IFERROR(INDEX('Matriz de Pesos'!$D$4:$D$36,MATCH($D$12,'Matriz de Pesos'!$A$4:$A$36,0)),0) -> 1 | C27: =IFERROR(INDEX('Matriz de Pesos'!$E$4:$E$36,MATCH($D$12,'Matriz de Pesos'!$A$4:$A$36,0)),0) -> 1 | D27: =IFERROR(INDEX('Matriz de Pesos'!$F$4:$F$36,MATCH($D$12,'Matriz de Pesos'!$A$4:$A$36,0)),0) -> 0 | E27: =IFERROR(INDEX('Matriz de Pesos'!$G$4:$G$36,MATCH($D$12,'Matriz de Pesos'!$A$4:$A$36,0)),0) -> 0 | F27: =IFERROR(INDEX('Matriz de Pesos'!$H$4:$H$36,MATCH($D$12,'Matriz de Pesos'!$A$4:$A$36,0)),0) -> 0 | G27: =IFERROR(INDEX('Matriz de Pesos'!$I$4:$I$36,MATCH($D$12,'Matriz de Pesos'!$A$4:$A$36,0)),0) -> 0 | H27: =IFERROR(INDEX('Matriz de Pesos'!$J$4:$J$36,MATCH($D$12,'Matriz de Pesos'!$A$4:$A$36,0)),0) -> 0 | I27: =IFERROR(INDEX('Matriz de Pesos'!$K$4:$K$36,MATCH($D$12,'Matriz de Pesos'!$A$4:$A$36,0)),0) -> 5 | J27: =IFERROR(INDEX('Matriz de Pesos'!$L$4:$L$36,MATCH($D$12,'Matriz de Pesos'!$A$4:$A$36,0)),0) -> 0 | K27: =IFERROR(INDEX('Matriz de Pesos'!$M$4:$M$36,MATCH($D$12,'Matriz de Pesos'!$A$4:$A$36,0)),0) -> 0 | L27: =IFERROR(INDEX('Matriz de Pesos'!$N$4:$N$36,MATCH($D$12,'Matriz de Pesos'!$A$4:$A$36,0)),0) -> 0
A28: ¿Tiene mascota (perro o gato)? | B28: =IFERROR(INDEX('Matriz de Pesos'!$D$4:$D$36,MATCH($D$13,'Matriz de Pesos'!$A$4:$A$36,0)),0) -> 0 | C28: =IFERROR(INDEX('Matriz de Pesos'!$E$4:$E$36,MATCH($D$13,'Matriz de Pesos'!$A$4:$A$36,0)),0) -> 0 | D28: =IFERROR(INDEX('Matriz de Pesos'!$F$4:$F$36,MATCH($D$13,'Matriz de Pesos'!$A$4:$A$36,0)),0) -> 0 | E28: =IFERROR(INDEX('Matriz de Pesos'!$G$4:$G$36,MATCH($D$13,'Matriz de Pesos'!$A$4:$A$36,0)),0) -> 0 | F28: =IFERROR(INDEX('Matriz de Pesos'!$H$4:$H$36,MATCH($D$13,'Matriz de Pesos'!$A$4:$A$36,0)),0) -> 0 | G28: =IFERROR(INDEX('Matriz de Pesos'!$I$4:$I$36,MATCH($D$13,'Matriz de Pesos'!$A$4:$A$36,0)),0) -> 0 | H28: =IFERROR(INDEX('Matriz de Pesos'!$J$4:$J$36,MATCH($D$13,'Matriz de Pesos'!$A$4:$A$36,0)),0) -> 5 | I28: =IFERROR(INDEX('Matriz de Pesos'!$K$4:$K$36,MATCH($D$13,'Matriz de Pesos'!$A$4:$A$36,0)),0) -> 0 | J28: =IFERROR(INDEX('Matriz de Pesos'!$L$4:$L$36,MATCH($D$13,'Matriz de Pesos'!$A$4:$A$36,0)),0) -> 0 | K28: =IFERROR(INDEX('Matriz de Pesos'!$M$4:$M$36,MATCH($D$13,'Matriz de Pesos'!$A$4:$A$36,0)),0) -> 0 | L28: =IFERROR(INDEX('Matriz de Pesos'!$N$4:$N$36,MATCH($D$13,'Matriz de Pesos'!$A$4:$A$36,0)),0) -> 0
A29: ¿Usa bicicleta como transporte o deporte habitual? | B29: =IFERROR(INDEX('Matriz de Pesos'!$D$4:$D$36,MATCH($D$14,'Matriz de Pesos'!$A$4:$A$36,0)),0) -> 0 | C29: =IFERROR(INDEX('Matriz de Pesos'!$E$4:$E$36,MATCH($D$14,'Matriz de Pesos'!$A$4:$A$36,0)),0) -> 0 | D29: =IFERROR(INDEX('Matriz de Pesos'!$F$4:$F$36,MATCH($D$14,'Matriz de Pesos'!$A$4:$A$36,0)),0) -> 0 | E29: =IFERROR(INDEX('Matriz de Pesos'!$G$4:$G$36,MATCH($D$14,'Matriz de Pesos'!$A$4:$A$36,0)),0) -> 0 | F29: =IFERROR(INDEX('Matriz de Pesos'!$H$4:$H$36,MATCH($D$14,'Matriz de Pesos'!$A$4:$A$36,0)),0) -> 0 | G29: =IFERROR(INDEX('Matriz de Pesos'!$I$4:$I$36,MATCH($D$14,'Matriz de Pesos'!$A$4:$A$36,0)),0) -> 0 | H29: =IFERROR(INDEX('Matriz de Pesos'!$J$4:$J$36,MATCH($D$14,'Matriz de Pesos'!$A$4:$A$36,0)),0) -> 0 | I29: =IFERROR(INDEX('Matriz de Pesos'!$K$4:$K$36,MATCH($D$14,'Matriz de Pesos'!$A$4:$A$36,0)),0) -> 0 | J29: =IFERROR(INDEX('Matriz de Pesos'!$L$4:$L$36,MATCH($D$14,'Matriz de Pesos'!$A$4:$A$36,0)),0) -> 0 | K29: =IFERROR(INDEX('Matriz de Pesos'!$M$4:$M$36,MATCH($D$14,'Matriz de Pesos'!$A$4:$A$36,0)),0) -> 0 | L29: =IFERROR(INDEX('Matriz de Pesos'!$N$4:$N$36,MATCH($D$14,'Matriz de Pesos'!$A$4:$A$36,0)),0) -> 0
A30: ¿Es jefatura de hogar femenina sin pareja? | B30: =IFERROR(INDEX('Matriz de Pesos'!$D$4:$D$36,MATCH($D$15,'Matriz de Pesos'!$A$4:$A$36,0)),0) -> 0 | C30: =IFERROR(INDEX('Matriz de Pesos'!$E$4:$E$36,MATCH($D$15,'Matriz de Pesos'!$A$4:$A$36,0)),0) -> 0 | D30: =IFERROR(INDEX('Matriz de Pesos'!$F$4:$F$36,MATCH($D$15,'Matriz de Pesos'!$A$4:$A$36,0)),0) -> 0 | E30: =IFERROR(INDEX('Matriz de Pesos'!$G$4:$G$36,MATCH($D$15,'Matriz de Pesos'!$A$4:$A$36,0)),0) -> 0 | F30: =IFERROR(INDEX('Matriz de Pesos'!$H$4:$H$36,MATCH($D$15,'Matriz de Pesos'!$A$4:$A$36,0)),0) -> 0 | G30: =IFERROR(INDEX('Matriz de Pesos'!$I$4:$I$36,MATCH($D$15,'Matriz de Pesos'!$A$4:$A$36,0)),0) -> 0 | H30: =IFERROR(INDEX('Matriz de Pesos'!$J$4:$J$36,MATCH($D$15,'Matriz de Pesos'!$A$4:$A$36,0)),0) -> 0 | I30: =IFERROR(INDEX('Matriz de Pesos'!$K$4:$K$36,MATCH($D$15,'Matriz de Pesos'!$A$4:$A$36,0)),0) -> 0 | J30: =IFERROR(INDEX('Matriz de Pesos'!$L$4:$L$36,MATCH($D$15,'Matriz de Pesos'!$A$4:$A$36,0)),0) -> 0 | K30: =IFERROR(INDEX('Matriz de Pesos'!$M$4:$M$36,MATCH($D$15,'Matriz de Pesos'!$A$4:$A$36,0)),0) -> 0 | L30: =IFERROR(INDEX('Matriz de Pesos'!$N$4:$N$36,MATCH($D$15,'Matriz de Pesos'!$A$4:$A$36,0)),0) -> 0
A31: PUNTAJE TOTAL | B31: =SUM(B20:B30) -> 24 | C31: =SUM(C20:C30) -> 16 | D31: =SUM(D20:D30) -> 18 | E31: =SUM(E20:E30) -> 16 | F31: =SUM(F20:F30) -> 19 | G31: =SUM(G20:G30) -> 13 | H31: =SUM(H20:H30) -> 21 | I31: =SUM(I20:I30) -> 21 | ... L31: =SUM(L20:L30) -> 11
A34: Ranking de seguros sugeridos para este perfil
A35: Ranking | B35: Seguro | C35: Línea | D35: Puntaje | E35: Puntaje máximo | F35: % del máximo
A36: =RANK(D36,$D$36:$D$46)+COUNTIF($D$36:D36,D36)-1 -> 1 | B36: Vida | C36: Familia | D36: =B$31 -> 24 | E36: ='Matriz de Pesos'!$D$38 -> 31 | F36: =IFERROR(D36/E36,0) -> 0.77419355
A37: =RANK(D37,$D$36:$D$46)+COUNTIF($D$36:D37,D37)-1 -> 7 | B37: Accidentes personales | C37: Familia | D37: =C$31 -> 16 | E37: ='Matriz de Pesos'!$E$38 -> 24 | F37: =IFERROR(D37/E37,0) -> 0.66666667
A38: =RANK(D38,$D$36:$D$46)+COUNTIF($D$36:D38,D38)-1 -> 5 | B38: Renta por hospitalización | C38: Familia | D38: =D$31 -> 18 | E38: ='Matriz de Pesos'!$F$38 -> 23 | F38: =IFERROR(D38/E38,0) -> 0.7826087
A39: =RANK(D39,$D$36:$D$46)+COUNTIF($D$36:D39,D39)-1 -> 8 | B39: Diagnóstico positivo de cáncer | C39: Familia | D39: =E$31 -> 16 | E39: ='Matriz de Pesos'!$G$38 -> 21 | F39: =IFERROR(D39/E39,0) -> 0.76190476
A40: =RANK(D40,$D$36:$D$46)+COUNTIF($D$36:D40,D40)-1 -> 4 | B40: Póliza de salud | C40: Familia | D40: =F$31 -> 19 | E40: ='Matriz de Pesos'!$H$38 -> 24 | F40: =IFERROR(D40/E40,0) -> 0.79166667
A41: =RANK(D41,$D$36:$D$46)+COUNTIF($D$36:D41,D41)-1 -> 9 | B41: Exequial familiar | C41: Familia | D41: =G$31 -> 13 | E41: ='Matriz de Pesos'!$I$38 -> 24 | F41: =IFERROR(D41/E41,0) -> 0.54166667
A42: =RANK(D42,$D$36:$D$46)+COUNTIF($D$36:D42,D42)-1 -> 2 | B42: Seguro de mascotas | C42: Familia | D42: =H$31 -> 21 | E42: ='Matriz de Pesos'!$J$38 -> 25 | F42: =IFERROR(D42/E42,0) -> 0.84
A43: =RANK(D43,$D$36:$D$46)+COUNTIF($D$36:D43,D43)-1 -> 3 | B43: Todo riesgo autos y motos | C43: Patrimonio | D43: =I$31 -> 21 | E43: ='Matriz de Pesos'!$K$38 -> 25 | F43: =IFERROR(D43/E43,0) -> 0.84
A44: =RANK(D44,$D$36:$D$46)+COUNTIF($D$36:D44,D44)-1 -> 6 | B44: Todo riesgo hogar | C44: Patrimonio | D44: =J$31 -> 17 | E44: ='Matriz de Pesos'!$L$38 -> 24 | F44: =IFERROR(D44/E44,0) -> 0.70833333
A45: =RANK(D45,$D$36:$D$46)+COUNTIF($D$36:D45,D45)-1 -> 11 | B45: Bicicletas | C45: Patrimonio | D45: =K$31 -> 10 | E45: ='Matriz de Pesos'!$M$38 -> 21 | F45: =IFERROR(D45/E45,0) -> 0.47619048
...

Sheet Datos de Mercado CO
A1: Ficha de estadísticas de mercado por seguro (Colombia)
A3: Seguro | B3: Línea | C3: Estadística clave de mercado | D3: Perfil con mayor probabilidad de compra | E3: Fuente
A4: Vida | B4: Familia | C4: Solo ~16% de la Población Económicamente Activa tiene seguro de vida individual. Penetración del ramo Vida: 1,14% del PIB. Consumo per cápita: ~$370.000/año. | D4: Perfil formal independiente/profesional sin seguro grupal empresarial; adultos 36-55 años con hijos menores (lógica HLV/DIME); jefatura de hogar femenina sin pareja. | E4: Fasecolda, dic-2024; Coriesgos, 2026
A5: Accidentes personales | B5: Familia | C5: Sin cifra agregada específica publicada por Fasecolda; se infiere del 55,4% de informalidad laboral (sin cobertura ARL) y de la alta accidentalidad de motociclistas (61-63% del parque, mayor siniestralidad vial). | D5: Trabajadores informales/cuenta propia sin ARL; conductores de moto; jóvenes 18-35 con actividades de riesgo (bicicleta, deporte). | E5: DANE, GEIH 2025; Fasecolda, 2024-2025
A6: Renta por hospitalización | B6: Familia | C6: Sin cifra de penetración específica publicada; producto típicamente ofrecido como anexo de vida o salud. Relevancia creciente con la edad por mayor probabilidad de hospitalización. | D6: Adultos 46-65+ años; hogares multigeneracionales con adulto mayor a cargo; independientes sin incapacidad pagada por EPS/empleador. | E6: Fasecolda — FAQ Vida y Personas, 2025
A7: Diagnóstico positivo de cáncer | B7: Familia | C7: ~81.596 casos nuevos y ~40.300 muertes por cáncer al año en Colombia. 53,2% de los casos en hombres y 38,3% en mujeres ocurren en 65+ años; 21,7% adicional en 55-64 años. | D7: Adultos desde 46 años en adelante, con pico en 56-65+; diferenciación por sexo (próstata/estómago en hombres, mama/cuello uterino en mujeres). | E7: Instituto Nacional de Cancerología (INC), 2022-2024
A8: Póliza de salud | B8: Familia | C8: ~4,25 millones de colombianos con algún esquema de salud voluntario (prepagada 51,8%, seguros de salud 31,9%, planes complementarios ~12%). El segmento de seguros de salud crece 14% anual, el más rápido de los cuatro. | D8: Clase media y alta (ingreso > $1.3M); formal dependiente e independiente; familias con hijos menores que buscan complementar el régimen contributivo. | E8: Fasecolda, Acemi, Proesa, 2024-2025
A9: Exequial familiar | B9: Familia | C9: 47,5% de los hogares tiene algún esquema de protección exequial (dato agregado, incluye planes funerarios amplios de comercializadoras); un estudio específico de pólizas fúnebres formales del sector asegurador reporta apenas 2,7% de los hogares (~385.000 familias). | D9: Estratos 1-3 (fuerte arraigo cultural); adultos mayores y hogares multigeneracionales; trabajadores informales sin otra protección. | E9: Superintendencia Financiera / Fasecolda / Banca de las Oportunidades, 2018; La República, 2021
A10: Seguro de mascotas | B10: Familia | C10: 60-70% de los hogares colombianos tiene mascota (65-68% perro, 43-48% gato). El mercado de seguros de mascotas crece 40% anual; cliente típico SURA: 30-50 años, 76% mujeres. | D10: Mujeres 26-50 años con mascota; familias de clase media y alta; fuerte alineación con el ICP de soycaropinzón (mujeres, decisiones inteligentes). | E10: DANE / Kantar Worldpanel, 2024-2026; Seguros SURA, ago-2024
A11: Todo riesgo autos y motos | B11: Patrimonio | C11: Solo 12,2% del parque automotor tiene seguro voluntario todo riesgo (27% en carros, 2,8-3% en motos, pese a que las motos son 61-63% del parque de 21,3 millones de vehículos). | D11: Propietarios de carro (alta prioridad); propietarios de moto (gran oportunidad sub-penetrada); estrato medio-alto. | E11: Fasecolda, 2024-2025
A12: Todo riesgo hogar | B12: Patrimonio | C12: Solo 9,3% de los hogares tiene seguro de vivienda voluntario (1,67 millones de 17,9 millones de hogares). Más del 70% de las pólizas de hogar están atadas a crédito hipotecario. | D12: Propietarios con vivienda financiada (casi obligatorio en la práctica); propietarios con vivienda pagada de estrato medio-alto. | E12: Fasecolda / Semana, mar-2026
A13: Bicicletas | B13: Patrimonio | C13: En Bogotá se hurta una bicicleta cada 2,5 horas en promedio (2025); tendencia a la baja interanual pero sigue siendo uno de los 10 bienes más hurtados de la ciudad. | D13: Usuarios habituales de bicicleta como transporte o deporte, especialmente 18-35 años en grandes ciudades. | E13: Secretaría de Seguridad de Bogotá / SIEDCO, 2024-2026
A14: Arrendamiento | B14: Patrimonio | C14: El costo de un seguro de arrendamiento equivale a 40-75% de un canon mensual; en Bogotá 1 de cada 4 contratos de arriendo termina en conflicto económico entre propietario e inquilino. | D14: Propietarios que arriendan un inmueble a terceros (variable de oportunidad de venta cruzada específica, no depende de la edad ni composición familiar del propietario). | E14: Coriesgos / Inmobiliare Latam, 2026
